---
layout: post
title: "Exception Handling in Constructors in C++"
description: " "
date: 2023-09-23
tags: [programming, Cplusplus]
comments: true
share: true
---

In object-oriented programming, constructors are special member functions that are used to initialize objects of a class. Constructors are called automatically when an object is created. However, constructors can also throw exceptions when there is an error during object initialization. In this blog post, we will explore exception handling in constructors in C++.

## Basics of Constructors

Before diving into exception handling, let's quickly recap constructors in C++. In C++, a constructor is defined within a class and has the same name as the class. The constructor is called automatically when an object is created and is responsible for initializing the data members of the object.

Here's an example of a simple constructor in C++:

```cpp
class MyClass {
public:
    MyClass() {
        // constructor code here
    }
};
```

## Exception Handling in Constructors

Constructors can throw exceptions just like any other function in C++. When an exception is thrown in a constructor, the object is not fully initialized. To handle such exceptions, we can use try-catch blocks or propagate the exception to the caller.

Let's consider an example where a constructor throws an exception:

```cpp
class BankAccount {
public:
    BankAccount(int amount) {
        if (amount < 0) {
            throw "Invalid amount";
        }
        balance = amount;
    }

    int getBalance() {
        return balance;
    }

private:
    int balance;
};
```

In the above example, the `BankAccount` constructor checks if the initial amount provided is negative. If it is, an exception is thrown with the error message "Invalid amount". Notice that the `balance` variable is not assigned in case of an exception.

To handle this exception, we can use a try-catch block:

```cpp
try {
    BankAccount account(-100);
    // other code here
} catch (const char* errorMessage) {
    std::cout << "Exception caught: " << errorMessage << std::endl;
}
```

In the above code, when the `BankAccount` constructor throws an exception, it is caught by the catch block, and the error message is displayed on the console.

## Ensuring Proper Cleanup

When an exception is thrown in a constructor, it's important to ensure proper cleanup of any resources that may have been allocated before the exception occurred.

For example, if a constructor allocates memory using `new`, it is necessary to deallocate that memory before the exception propagates. This can be done by using a try-catch block inside the constructor itself or by using smart pointers.

```cpp
class MyClass {
public:
    MyClass() {
        resource = new Resource();  // allocate resource
        // other constructor code
    }

    ~MyClass() {
        delete resource;  // deallocate resource in destructor
    }

private:
    Resource* resource;
};
```

In the above example, the constructor allocates a resource using `new`. In the destructor, the resource is deallocated using `delete`.

## Conclusion

Exception handling in constructors allows us to handle errors that occur during object initialization. By using try-catch blocks or propagating exceptions, we can ensure that objects are properly initialized and any resources are cleaned up in case of an exception.

Remember to handle exceptions properly within constructors to prevent memory leaks and ensure robust error handling.

#programming #Cplusplus